2016-10-23T13:24:49.288798+00:00 heroku[web.1]: Process exited with status 3
2016-10-23T13:24:49.305623+00:00 heroku[web.1]: State changed from up to crashed
2016-10-23T13:30:09.188036+00:00 heroku[api]: Deploy 2b6a478 by subil1407@gmail.com
2016-10-23T13:30:09.188093+00:00 heroku[api]: Release v7 created by subil1407@gmail.com
2016-10-23T13:30:09.402087+00:00 heroku[slug-compiler]: Slug compilation started
2016-10-23T13:30:09.402096+00:00 heroku[slug-compiler]: Slug compilation finished
2016-10-23T13:30:09.378989+00:00 heroku[web.1]: State changed from crashed to starting
2016-10-23T13:30:13.225539+00:00 heroku[web.1]: Starting process with command `gunicorn run:app --log-file -`
2016-10-23T13:30:16.306611+00:00 app[web.1]: [2016-10-23 13:30:16 +0000] [3] [INFO] Starting gunicorn 19.6.0
2016-10-23T13:30:16.307359+00:00 app[web.1]: [2016-10-23 13:30:16 +0000] [3] [INFO] Listening at: http://0.0.0.0:35686 (3)
2016-10-23T13:30:16.307504+00:00 app[web.1]: [2016-10-23 13:30:16 +0000] [3] [INFO] Using worker: sync
2016-10-23T13:30:16.313834+00:00 app[web.1]: [2016-10-23 13:30:16 +0000] [7] [INFO] Booting worker with pid: 7
2016-10-23T13:30:16.391015+00:00 app[web.1]: [2016-10-23 13:30:16 +0000] [8] [INFO] Booting worker with pid: 8
2016-10-23T13:30:16.882471+00:00 heroku[web.1]: State changed from starting to up
2016-10-23T13:30:22.659505+00:00 app[web.1]: [2016-10-23 13:30:22 +0000] [8] [ERROR] Exception in worker process
2016-10-23T13:30:22.659522+00:00 app[web.1]: Traceback (most recent call last):
2016-10-23T13:30:22.659524+00:00 app[web.1]:     worker.init_process()
2016-10-23T13:30:22.659525+00:00 app[web.1]:   File "/app/.heroku/python/lib/python3.5/site-packages/gunicorn/workers/base.py", line 126, in init_process
2016-10-23T13:30:22.659525+00:00 app[web.1]:     self.load_wsgi()
2016-10-23T13:30:22.659526+00:00 app[web.1]:   File "/app/.heroku/python/lib/python3.5/site-packages/gunicorn/workers/base.py", line 136, in load_wsgi
2016-10-23T13:30:22.659527+00:00 app[web.1]:     self.wsgi = self.app.wsgi()
2016-10-23T13:30:22.659528+00:00 app[web.1]:   File "/app/.heroku/python/lib/python3.5/site-packages/gunicorn/app/base.py", line 67, in wsgi
2016-10-23T13:30:22.659529+00:00 app[web.1]:     self.callable = self.load()
2016-10-23T13:30:22.659530+00:00 app[web.1]:     return self.load_wsgiapp()
2016-10-23T13:30:22.659531+00:00 app[web.1]:   File "/app/.heroku/python/lib/python3.5/site-packages/gunicorn/app/wsgiapp.py", line 52, in load_wsgiapp
2016-10-23T13:30:22.659532+00:00 app[web.1]:   File "/app/.heroku/python/lib/python3.5/site-packages/gunicorn/util.py", line 357, in import_app
2016-10-23T13:30:22.659531+00:00 app[web.1]:     return util.import_app(self.app_uri)
2016-10-23T13:30:22.659533+00:00 app[web.1]:   File "/app/run.py", line 7, in <module>
2016-10-23T13:30:22.659533+00:00 app[web.1]:     __import__(module)
2016-10-23T13:30:22.659534+00:00 app[web.1]:     app.run(debug=True, use_reloader=True, port=port)
2016-10-23T13:30:22.659535+00:00 app[web.1]:   File "/app/.heroku/python/lib/python3.5/site-packages/flask/app.py", line 843, in run
2016-10-23T13:30:22.659536+00:00 app[web.1]:     run_simple(host, port, self, **options)
2016-10-23T13:30:22.659523+00:00 app[web.1]:   File "/app/.heroku/python/lib/python3.5/site-packages/gunicorn/arbiter.py", line 557, in spawn_worker
2016-10-23T13:30:22.659537+00:00 app[web.1]:     s.bind((hostname, port))
2016-10-23T13:30:22.659898+00:00 app[web.1]: [2016-10-23 13:30:22 +0000] [8] [INFO] Worker exiting (pid: 8)
2016-10-23T13:30:22.659529+00:00 app[web.1]:   File "/app/.heroku/python/lib/python3.5/site-packages/gunicorn/app/wsgiapp.py", line 65, in load
2016-10-23T13:30:22.659542+00:00 app[web.1]: OSError: [Errno 98] Address already in use
2016-10-23T13:30:22.660301+00:00 app[web.1]: sys:1: ResourceWarning: unclosed <socket.socket fd=13, family=AddressFamily.AF_INET, type=SocketKind.SOCK_STREAM, proto=0, laddr=('0.0.0.0', 0)>
2016-10-23T13:30:22.659537+00:00 app[web.1]:   File "/app/.heroku/python/lib/python3.5/site-packages/werkzeug/serving.py", line 677, in run_simple
2016-10-23T13:30:24.076912+00:00 app[web.1]: [2016-10-23 13:30:24 +0000] [7] [ERROR] Exception in worker process
2016-10-23T13:30:24.076922+00:00 app[web.1]: Traceback (most recent call last):
2016-10-23T13:30:24.076923+00:00 app[web.1]:   File "/app/.heroku/python/lib/python3.5/site-packages/gunicorn/arbiter.py", line 557, in spawn_worker
2016-10-23T13:30:24.076924+00:00 app[web.1]:     worker.init_process()
2016-10-23T13:30:24.076924+00:00 app[web.1]:   File "/app/.heroku/python/lib/python3.5/site-packages/gunicorn/workers/base.py", line 126, in init_process
2016-10-23T13:30:24.076925+00:00 app[web.1]:     self.load_wsgi()
2016-10-23T13:30:24.076925+00:00 app[web.1]:   File "/app/.heroku/python/lib/python3.5/site-packages/gunicorn/workers/base.py", line 136, in load_wsgi
2016-10-23T13:30:24.076926+00:00 app[web.1]:     self.wsgi = self.app.wsgi()
2016-10-23T13:30:24.076926+00:00 app[web.1]:   File "/app/.heroku/python/lib/python3.5/site-packages/gunicorn/app/base.py", line 67, in wsgi
2016-10-23T13:30:24.076927+00:00 app[web.1]:     self.callable = self.load()
2016-10-23T13:30:24.076927+00:00 app[web.1]:   File "/app/.heroku/python/lib/python3.5/site-packages/gunicorn/app/wsgiapp.py", line 65, in load
2016-10-23T13:30:24.076928+00:00 app[web.1]:     return self.load_wsgiapp()
2016-10-23T13:30:24.076928+00:00 app[web.1]:   File "/app/.heroku/python/lib/python3.5/site-packages/gunicorn/app/wsgiapp.py", line 52, in load_wsgiapp
2016-10-23T13:30:24.076929+00:00 app[web.1]:     return util.import_app(self.app_uri)
2016-10-23T13:30:24.076929+00:00 app[web.1]:   File "/app/.heroku/python/lib/python3.5/site-packages/gunicorn/util.py", line 357, in import_app
2016-10-23T13:30:24.076930+00:00 app[web.1]:   File "/app/run.py", line 7, in <module>
2016-10-23T13:30:24.076929+00:00 app[web.1]:     __import__(module)
2016-10-23T13:30:24.076930+00:00 app[web.1]:     app.run(debug=True, use_reloader=True, port=port)
2016-10-23T13:30:24.076931+00:00 app[web.1]:   File "/app/.heroku/python/lib/python3.5/site-packages/flask/app.py", line 843, in run
2016-10-23T13:30:24.076931+00:00 app[web.1]:     run_simple(host, port, self, **options)
2016-10-23T13:30:24.076933+00:00 app[web.1]:   File "/app/.heroku/python/lib/python3.5/site-packages/werkzeug/serving.py", line 677, in run_simple
2016-10-23T13:30:24.076934+00:00 app[web.1]:     s.bind((hostname, port))
2016-10-23T13:30:24.077528+00:00 app[web.1]: [2016-10-23 13:30:24 +0000] [7] [INFO] Worker exiting (pid: 7)
2016-10-23T13:30:24.076937+00:00 app[web.1]: OSError: [Errno 98] Address already in use
2016-10-23T13:30:24.078053+00:00 app[web.1]: sys:1: ResourceWarning: unclosed <socket.socket fd=12, family=AddressFamily.AF_INET, type=SocketKind.SOCK_STREAM, proto=0, laddr=('0.0.0.0', 0)>
2016-10-23T13:30:24.078630+00:00 app[web.1]: sys:1: ResourceWarning: unclosed <socket.socket fd=6, family=AddressFamily.AF_INET, type=2049, proto=0, laddr=('0.0.0.0', 35686)>
2016-10-23T13:30:24.150193+00:00 app[web.1]:   File "/app/.heroku/python/lib/python3.5/site-packages/gunicorn/arbiter.py", line 346, in sleep
2016-10-23T13:30:24.150421+00:00 app[web.1]:     ready = select.select([self.PIPE[0]], [], [], 1.0)
2016-10-23T13:30:24.149940+00:00 app[web.1]: Traceback (most recent call last):
2016-10-23T13:30:24.149947+00:00 app[web.1]:   File "/app/.heroku/python/lib/python3.5/site-packages/gunicorn/arbiter.py", line 196, in run
2016-10-23T13:30:24.150191+00:00 app[web.1]:     self.sleep()
2016-10-23T13:30:24.150604+00:00 app[web.1]:   File "/app/.heroku/python/lib/python3.5/site-packages/gunicorn/arbiter.py", line 506, in reap_workers
2016-10-23T13:30:24.150825+00:00 app[web.1]:     raise HaltServer(reason, self.WORKER_BOOT_ERROR)
2016-10-23T13:30:24.150423+00:00 app[web.1]:   File "/app/.heroku/python/lib/python3.5/site-packages/gunicorn/arbiter.py", line 231, in handle_chld
2016-10-23T13:30:24.150854+00:00 app[web.1]: gunicorn.errors.HaltServer: <HaltServer 'Worker failed to boot.' 3>
2016-10-23T13:30:24.150856+00:00 app[web.1]: 
2016-10-23T13:30:24.150600+00:00 app[web.1]:     self.reap_workers()
2016-10-23T13:30:24.150857+00:00 app[web.1]: During handling of the above exception, another exception occurred:
2016-10-23T13:30:24.150857+00:00 app[web.1]: 
2016-10-23T13:30:24.150860+00:00 app[web.1]: Traceback (most recent call last):
2016-10-23T13:30:24.150861+00:00 app[web.1]:   File "/app/.heroku/python/bin/gunicorn", line 11, in <module>
2016-10-23T13:30:24.150962+00:00 app[web.1]:     sys.exit(run())
2016-10-23T13:30:24.150964+00:00 app[web.1]:   File "/app/.heroku/python/lib/python3.5/site-packages/gunicorn/app/wsgiapp.py", line 74, in run
2016-10-23T13:30:24.151073+00:00 app[web.1]:     WSGIApplication("%(prog)s [OPTIONS] [APP_MODULE]").run()
2016-10-23T13:30:24.151074+00:00 app[web.1]:   File "/app/.heroku/python/lib/python3.5/site-packages/gunicorn/app/base.py", line 192, in run
2016-10-23T13:30:24.151210+00:00 app[web.1]:     super(Application, self).run()
2016-10-23T13:30:24.151212+00:00 app[web.1]:   File "/app/.heroku/python/lib/python3.5/site-packages/gunicorn/app/base.py", line 72, in run
2016-10-23T13:30:24.151316+00:00 app[web.1]:     Arbiter(self).run()
2016-10-23T13:30:24.151322+00:00 app[web.1]:   File "/app/.heroku/python/lib/python3.5/site-packages/gunicorn/arbiter.py", line 218, in run
2016-10-23T13:30:24.151459+00:00 app[web.1]:     self.halt(reason=inst.reason, exit_status=inst.exit_status)
2016-10-23T13:30:24.151461+00:00 app[web.1]:   File "/app/.heroku/python/lib/python3.5/site-packages/gunicorn/arbiter.py", line 331, in halt
2016-10-23T13:30:24.151646+00:00 app[web.1]:     self.stop()
2016-10-23T13:30:24.151647+00:00 app[web.1]:   File "/app/.heroku/python/lib/python3.5/site-packages/gunicorn/arbiter.py", line 381, in stop
2016-10-23T13:30:24.151822+00:00 app[web.1]:     time.sleep(0.1)
2016-10-23T13:30:24.151824+00:00 app[web.1]:   File "/app/.heroku/python/lib/python3.5/site-packages/gunicorn/arbiter.py", line 231, in handle_chld
2016-10-23T13:30:24.151955+00:00 app[web.1]:     self.reap_workers()
2016-10-23T13:30:24.151956+00:00 app[web.1]:   File "/app/.heroku/python/lib/python3.5/site-packages/gunicorn/arbiter.py", line 506, in reap_workers
2016-10-23T13:30:24.152149+00:00 app[web.1]:     raise HaltServer(reason, self.WORKER_BOOT_ERROR)
2016-10-23T13:30:24.152166+00:00 app[web.1]: gunicorn.errors.HaltServer: <HaltServer 'Worker failed to boot.' 3>
2016-10-23T13:30:24.233185+00:00 heroku[web.1]: Process exited with status 1
2016-10-23T13:30:24.211413+00:00 heroku[web.1]: State changed from up to crashed
2016-10-23T13:30:32.363582+00:00 heroku[router]: at=error code=H10 desc="App crashed" method=GET path="/" host=daily-reddit.herokuapp.com request_id=bad75d85-1c6c-40ae-92f7-f52341843e00 fwd="117.216.137.226" dyno= connect= service= status=503 bytes=
